[32m2023-06-11 17:55:35 +0200[0m - dagster - [34mDEBUG[0m - single_foi_request - 92cd0fbd-6f28-4d53-88ea-d417f2d42d95 - 238699 - LOGS_CAPTURED - Started capturing logs in process (pid: 238699).
[32m2023-06-11 17:55:35 +0200[0m - dagster - [34mDEBUG[0m - single_foi_request - 92cd0fbd-6f28-4d53-88ea-d417f2d42d95 - 238699 - get_foi_request - STEP_START - Started execution of step "get_foi_request".
[32m2023-06-11 17:55:35 +0200[0m - dagster - [34mERROR[0m - [31msingle_foi_request - 92cd0fbd-6f28-4d53-88ea-d417f2d42d95 - 238699 - get_foi_request - STEP_FAILURE - Execution of step "get_foi_request" failed.

dagster._core.errors.DagsterExecutionInterruptedError

Stack Trace:
  File "/home/jstet/Code/CorrelAid/fds_pipeline/.venv/lib/python3.11/site-packages/dagster/_core/execution/plan/execute_plan.py", line 273, in dagster_event_sequence_for_step
    for step_event in check.generator(step_events):
  File "/home/jstet/Code/CorrelAid/fds_pipeline/.venv/lib/python3.11/site-packages/dagster/_core/execution/plan/execute_step.py", line 369, in core_dagster_event_sequence_for_step
    for user_event in check.generator(
  File "/home/jstet/Code/CorrelAid/fds_pipeline/.venv/lib/python3.11/site-packages/dagster/_core/execution/plan/execute_step.py", line 90, in _step_output_error_checked_user_event_sequence
    for user_event in user_event_sequence:
  File "/home/jstet/Code/CorrelAid/fds_pipeline/.venv/lib/python3.11/site-packages/dagster/_core/execution/plan/compute.py", line 192, in execute_core_compute
    for step_output in _yield_compute_results(step_context, inputs, compute_fn):
  File "/home/jstet/Code/CorrelAid/fds_pipeline/.venv/lib/python3.11/site-packages/dagster/_core/execution/plan/compute.py", line 161, in _yield_compute_results
    for event in iterate_with_context(
  File "/home/jstet/Code/CorrelAid/fds_pipeline/.venv/lib/python3.11/site-packages/dagster/_utils/__init__.py", line 443, in iterate_with_context
    with context_fn():
  File "/usr/lib/python3.11/contextlib.py", line 137, in __enter__
    return next(self.gen)
           ^^^^^^^^^^^^^^
  File "/home/jstet/Code/CorrelAid/fds_pipeline/.venv/lib/python3.11/site-packages/dagster/_core/execution/plan/utils.py", line 49, in op_execution_error_boundary
    with raise_execution_interrupts():
  File "/usr/lib/python3.11/contextlib.py", line 137, in __enter__
    return next(self.gen)
           ^^^^^^^^^^^^^^
  File "/home/jstet/Code/CorrelAid/fds_pipeline/.venv/lib/python3.11/site-packages/dagster/_core/errors.py", line 254, in raise_execution_interrupts
    with raise_interrupts_as(DagsterExecutionInterruptedError):
  File "/usr/lib/python3.11/contextlib.py", line 137, in __enter__
    return next(self.gen)
           ^^^^^^^^^^^^^^
  File "/home/jstet/Code/CorrelAid/fds_pipeline/.venv/lib/python3.11/site-packages/dagster/_utils/interrupts.py", line 93, in raise_interrupts_as
    raise error_cls()
[0m
